Workbook
Name hhhhhhhhhhhhhh: #REF!
Name proyAnterior: #REF!

Sheet an
A1: articulo | B1: pond | C1: b_s | D1: t_nt | E1: suby | F1: 44197 | G1: 44228 | H1: 44256 | I1: 44287 | J1: 44317 | K1: 44348 | L1: 44378 | M1: 44409 | N1: 44440 | O1: 44470 | P1: 44501 | Q1: 44531 | R1: 44562 | S1: 44593 | T1: 44621 | U1: 44652 | V1: 44682 | W1: 44713 | X1: 44743 | Y1: 44774 | Z1: 44805 | AA1: 44835 | AB1: 44866 | AC1: 44896 | AD1: 44927 | AE1: 44958 | AF1: 44986 | AG1: 45017 | AH1: 45047 | AI1: 45078 | AJ1: 45108 | AK1: 45139 | AL1: 45170 | AM1: 45200 | AN1: 45231 | AO1: 45261 | AP1: 45292 | AQ1: 45323 | AR1: 45352 | AS1: 45383 | AT1: 45413 | AU1: 45444 | AV1: 45474 | AW1: 45505 | AX1: 45536 | AY1: 45566 | AZ1: 45597 | BA1: 45627 | BB1: 45658 | BC1: 45689 | BD1: 45717 | BE1: 45748 | BF1: 45778 | BG1: 45809
A2: Pan sobado | B2: 0.50544517 | C2: B | D2: NT | E2: Suby | F2: =100*index!X2/index!L2-100 -> 0.49505922 | G2: =100*index!Y2/index!M2-100 -> 1.1261503 | H2: =100*index!Z2/index!N2-100 -> 1.1702909 | I2: =100*index!AA2/index!O2-100 -> 1.1192086 | J2: =100*index!AB2/index!P2-100 -> 1.078483 | K2: =100*index!AC2/index!Q2-100 -> 8.5625546 | L2: =100*index!AD2/index!R2-100 -> 18.65751 | M2: =100*index!AE2/index!S2-100 -> 17.113805 | ... BG2: =100*index!BY2/index!BM2-100 -> 2.02773
A3: Pan de agua | B3: 0.39901799 | C3: B | D3: NT | E3: Suby | F3: =100*index!X3/index!L3-100 -> 0.33266739 | G3: =100*index!Y3/index!M3-100 -> 0.33685361 | H3: =100*index!Z3/index!N3-100 -> 0.28219575 | I3: =100*index!AA3/index!O3-100 -> 0.42570836 | J3: =100*index!AB3/index!P3-100 -> 0.47896319 | K3: =100*index!AC3/index!Q3-100 -> 7.9989035 | L3: =100*index!AD3/index!R3-100 -> 16.274148 | M3: =100*index!AE3/index!S3-100 -> 14.84255 | ... BG3: =100*index!BY3/index!BM3-100 -> 1.5805649
A4: Pan Integral | B4: 0.040454533 | C4: B | D4: T | E4: Suby | F4: =100*index!X4/index!L4-100 -> 0.74559321 | G4: =100*index!Y4/index!M4-100 -> 0.96533292 | H4: =100*index!Z4/index!N4-100 -> 1.4145616 | I4: =100*index!AA4/index!O4-100 -> 1.8460317 | J4: =100*index!AB4/index!P4-100 -> 1.545794 | K4: =100*index!AC4/index!Q4-100 -> 2.8663132 | L4: =100*index!AD4/index!R4-100 -> 5.8961057 | M4: =100*index!AE4/index!S4-100 -> 6.2028662 | ... BG4: =100*index!BY4/index!BM4-100 -> 2.2303882
A5: Galletas saladas | B5: 0.13258761 | C5: B | D5: T | E5: Suby | F5: =100*index!X5/index!L5-100 -> 10.956148 | G5: =100*index!Y5/index!M5-100 -> 14.701867 | H5: =100*index!Z5/index!N5-100 -> 16.453625 | I5: =100*index!AA5/index!O5-100 -> 17.666805 | J5: =100*index!AB5/index!P5-100 -> 19.263725 | K5: =100*index!AC5/index!Q5-100 -> 20.36086 | L5: =100*index!AD5/index!R5-100 -> 21.896767 | M5: =100*index!AE5/index!S5-100 -> 22.127101 | ... BG5: =100*index!BY5/index!BM5-100 -> 2.7922533
A6: Bizcochos | B6: 0.077885033 | C6: B | D6: T | E6: Suby | F6: =100*index!X6/index!L6-100 -> 1.7764758 | G6: =100*index!Y6/index!M6-100 -> 1.6091301 | H6: =100*index!Z6/index!N6-100 -> 1.575524 | I6: =100*index!AA6/index!O6-100 -> 1.5166423 | J6: =100*index!AB6/index!P6-100 -> 1.1717308 | K6: =100*index!AC6/index!Q6-100 -> 1.063282 | L6: =100*index!AD6/index!R6-100 -> 1.1187023 | M6: =100*index!AE6/index!S6-100 -> 1.1422196 | ... BG6: =100*index!BY6/index!BM6-100 -> 2.9512693
A7: Galletas dulces | B7: 0.071040732 | C7: B | D7: T | E7: Suby | F7: =100*index!X7/index!L7-100 -> 5.1874095 | G7: =100*index!Y7/index!M7-100 -> 5.9016326 | H7: =100*index!Z7/index!N7-100 -> 6.3483204 | I7: =100*index!AA7/index!O7-100 -> 5.8279011 | J7: =100*index!AB7/index!P7-100 -> 6.8849521 | K7: =100*index!AC7/index!Q7-100 -> 7.3314396 | L7: =100*index!AD7/index!R7-100 -> 7.3115562 | M7: =100*index!AE7/index!S7-100 -> 7.0995605 | ... BG7: =100*index!BY7/index!BM7-100 -> 3.9660961
A8: Galletas de harina | B8: 0.020645883 | C8: B | D8: NT | E8: Suby | F8: =100*index!X8/index!L8-100 -> 0.72512171 | G8: =100*index!Y8/index!M8-100 -> 1.261311 | H8: =100*index!Z8/index!N8-100 -> 1.7589476 | I8: =100*index!AA8/index!O8-100 -> 1.4765236 | J8: =100*index!AB8/index!P8-100 -> 1.5801597 | K8: =100*index!AC8/index!Q8-100 -> 2.821758 | L8: =100*index!AD8/index!R8-100 -> 9.3996374 | M8: =100*index!AE8/index!S8-100 -> 9.5218941 | ... BG8: =100*index!BY8/index!BM8-100 -> 3.4040361
A9: Galletas de soda | B9: 0.050453635 | C9: B | D9: T | E9: Suby | F9: =100*index!X9/index!L9-100 -> 5.9057802 | G9: =100*index!Y9/index!M9-100 -> 6.2734282 | H9: =100*index!Z9/index!N9-100 -> 6.5836141 | I9: =100*index!AA9/index!O9-100 -> 5.6725713 | J9: =100*index!AB9/index!P9-100 -> 6.0493912 | K9: =100*index!AC9/index!Q9-100 -> 5.7904731 | L9: =100*index!AD9/index!R9-100 -> 5.1993043 | M9: =100*index!AE9/index!S9-100 -> 5.0787582 | ... BG9: =100*index!BY9/index!BM9-100 -> 2.5295668
A10: Galletas integrales | B10: 0.019352848 | C10: B | D10: T | E10: Suby | F10: =100*index!X10/index!L10-100 -> 1.587699 | G10: =100*index!Y10/index!M10-100 -> 1.0137729 | H10: =100*index!Z10/index!N10-100 -> 0.93072053 | I10: =100*index!AA10/index!O10-100 -> 0.96110864 | J10: =100*index!AB10/index!P10-100 -> 0.79787635 | K10: =100*index!AC10/index!Q10-100 -> 2.0099751 | L10: =100*index!AD10/index!R10-100 -> 3.818087 | M10: =100*index!AE10/index!S10-100 -> 6.0321058 | ... BG10: =100*index!BY10/index!BM10-100 -> 3.8678977
A11: Corn Flakes | B11: 0.10689881 | C11: B | D11: T | E11: Suby | F11: =100*index!X11/index!L11-100 -> 7.8941771 | G11: =100*index!Y11/index!M11-100 -> 10.20709 | H11: =100*index!Z11/index!N11-100 -> 11.806077 | I11: =100*index!AA11/index!O11-100 -> 8.9331058 | J11: =100*index!AB11/index!P11-100 -> 9.9722261 | K11: =100*index!AC11/index!Q11-100 -> 7.9944912 | L11: =100*index!AD11/index!R11-100 -> 7.301542 | M11: =100*index!AE11/index!S11-100 -> 6.023427 | ... BG11: =100*index!BY11/index!BM11-100 -> 2.1008503
A12: Avena | B12: 0.071995783 | C12: B | D12: T | E12: Suby | F12: =100*index!X12/index!L12-100 -> 6.0463553 | G12: =100*index!Y12/index!M12-100 -> 5.8548183 | H12: =100*index!Z12/index!N12-100 -> 5.6573171 | I12: =100*index!AA12/index!O12-100 -> 4.7324118 | J12: =100*index!AB12/index!P12-100 -> 4.6185814 | K12: =100*index!AC12/index!Q12-100 -> 3.9070652 | L12: =100*index!AD12/index!R12-100 -> 3.4167805 | M12: =100*index!AE12/index!S12-100 -> 3.8449862 | ... BG12: =100*index!BY12/index!BM12-100 -> 1.2877514
A13: Harina de maíz | B13: 0.043458139 | C13: B | D13: T | E13: Suby | F13: =100*index!X13/index!L13-100 -> 12.360941 | G13: =100*index!Y13/index!M13-100 -> 14.899841 | H13: =100*index!Z13/index!N13-100 -> 15.985396 | I13: =100*index!AA13/index!O13-100 -> 16.598767 | J13: =100*index!AB13/index!P13-100 -> 18.084881 | K13: =100*index!AC13/index!Q13-100 -> 24.222023 | L13: =100*index!AD13/index!R13-100 -> 25.070104 | M13: =100*index!AE13/index!S13-100 -> 25.870191 | ... BG13: =100*index!BY13/index!BM13-100 -> 3.1919586
... A365: Trámite para pasaporte (renovación) | B365: 0.027261408 | C365: S | D365: NT | E365: Suby | F365: =100*index!X365/index!L365-100 -> 0 | G365: =100*index!Y365/index!M365-100 -> 0 | H365: =100*index!Z365/index!N365-100 -> 0 | I365: =100*index!AA365/index!O365-100 -> 0 | J365: =100*index!AB365/index!P365-100 -> 0 | K365: =100*index!AC365/index!Q365-100 -> 0 | L365: =100*index!AD365/index!R365-100 -> 0 | M365: =100*index!AE365/index!S365-100 -> 0 | ... BG365: =100*index!BY365/index!BM365-100 -> 0

Sheet men
A1: articulo | B1: pond | C1: b_s | D1: t_nt | E1: suby | F1: 44197 | G1: 44228 | H1: 44256 | I1: 44287 | J1: 44317 | K1: 44348 | L1: 44378 | M1: 44409 | N1: 44440 | O1: 44470 | P1: 44501 | Q1: 44531 | R1: 44562 | S1: 44593 | T1: 44621 | U1: 44652 | V1: 44682 | W1: 44713 | X1: 44743 | Y1: 44774 | Z1: 44805 | AA1: 44835 | AB1: 44866 | AC1: 44896 | AD1: 44927 | AE1: 44958 | AF1: 44986 | AG1: 45017 | AH1: 45047 | AI1: 45078 | AJ1: 45108 | AK1: 45139 | AL1: 45170 | AM1: 45200 | AN1: 45231 | AO1: 45261 | AP1: 45292 | AQ1: 45323 | AR1: 45352 | AS1: 45383 | AT1: 45413 | AU1: 45444 | AV1: 45474 | AW1: 45505 | AX1: 45536 | AY1: 45566 | AZ1: 45597 | BA1: 45627 | BB1: 45658 | BC1: 45689 | BD1: 45717 | BE1: 45748 | BF1: 45778 | BG1: 45809
A2: Pan sobado | B2: 0.50544517 | C2: B | D2: NT | E2: Suby | F2: =100*index!X2/index!W2-100 -> 0.10569665 | G2: =100*index!Y2/index!X2-100 -> 0.63550248 | H2: =100*index!Z2/index!Y2-100 -> 0.25437737 | I2: =100*index!AA2/index!Z2-100 -> 0.037516784 | J2: =100*index!AB2/index!AA2-100 -> 0 | K2: =100*index!AC2/index!AB2-100 -> 7.3682964 | L2: =100*index!AD2/index!AC2-100 -> 9.0879844 | M2: =100*index!AE2/index!AD2-100 -> -1.3439614 | ... BG2: =100*index!BY2/index!BX2-100 -> 0.55061894
A3: Pan de agua | B3: 0.39901799 | C3: B | D3: NT | E3: Suby | F3: =100*index!X3/index!W3-100 -> 0.03591739 | G3: =100*index!Y3/index!X3-100 -> 0.041888576 | H3: =100*index!Z3/index!Y3-100 -> 0.11265303 | I3: =100*index!AA3/index!Z3-100 -> 0 | J3: =100*index!AB3/index!AA3-100 -> 0.090618496 | K3: =100*index!AC3/index!AB3-100 -> 7.5911334 | L3: =100*index!AD3/index!AC3-100 -> 7.5410109 | M3: =100*index!AE3/index!AD3-100 -> -1.1771585 | ... BG3: =100*index!BY3/index!BX3-100 -> 0.13910521
A4: Pan Integral | B4: 0.040454533 | C4: B | D4: T | E4: Suby | F4: =100*index!X4/index!W4-100 -> 0.17673137 | G4: =100*index!Y4/index!X4-100 -> 0.38772439 | H4: =100*index!Z4/index!Y4-100 -> 0.44579916 | I4: =100*index!AA4/index!Z4-100 -> 0.67709826 | J4: =100*index!AB4/index!AA4-100 -> 0.080508974 | K4: =100*index!AC4/index!AB4-100 -> 1.4303373 | L4: =100*index!AD4/index!AC4-100 -> 2.6907304 | M4: =100*index!AE4/index!AD4-100 -> 0.31457796 | ... BG4: =100*index!BY4/index!BX4-100 -> 0.5442232
A5: Galletas saladas | B5: 0.13258761 | C5: B | D5: T | E5: Suby | F5: =100*index!X5/index!W5-100 -> 3.563157 | G5: =100*index!Y5/index!X5-100 -> 3.5021322 | H5: =100*index!Z5/index!Y5-100 -> 1.5133622 | I5: =100*index!AA5/index!Z5-100 -> 1.263303 | J5: =100*index!AB5/index!AA5-100 -> 1.558152 | K5: =100*index!AC5/index!AB5-100 -> 1.4722394 | L5: =100*index!AD5/index!AC5-100 -> 1.3311423 | M5: =100*index!AE5/index!AD5-100 -> 0.57859524 | ... BG5: =100*index!BY5/index!BX5-100 -> -0.059891216
A6: Bizcochos | B6: 0.077885033 | C6: B | D6: T | E6: Suby | F6: =100*index!X6/index!W6-100 -> 0.025686623 | G6: =100*index!Y6/index!X6-100 -> 0.099757027 | H6: =100*index!Z6/index!Y6-100 -> 0.025654435 | I6: =100*index!AA6/index!Z6-100 -> -0.011837472 | J6: =100*index!AB6/index!AA6-100 -> 0.10161699 | K6: =100*index!AC6/index!AB6-100 -> 0.14980683 | L6: =100*index!AD6/index!AC6-100 -> 0.21354905 | M6: =100*index!AE6/index!AD6-100 -> 0.054991997 | ... BG6: =100*index!BY6/index!BX6-100 -> 0.11011843
A7: Galletas dulces | B7: 0.071040732 | C7: B | D7: T | E7: Suby | F7: =100*index!X7/index!W7-100 -> 0.70726154 | G7: =100*index!Y7/index!X7-100 -> 0.87546299 | H7: =100*index!Z7/index!Y7-100 -> 0.43202518 | I7: =100*index!AA7/index!Z7-100 -> 0.59919474 | J7: =100*index!AB7/index!AA7-100 -> 1.3762637 | K7: =100*index!AC7/index!AB7-100 -> 0.64620055 | L7: =100*index!AD7/index!AC7-100 -> 0.61614751 | M7: =100*index!AE7/index!AD7-100 -> 0.60869645 | ... BG7: =100*index!BY7/index!BX7-100 -> 0.37266932
A8: Galletas de harina | B8: 0.020645883 | C8: B | D8: NT | E8: Suby | F8: =100*index!X8/index!W8-100 -> 0.022870098 | G8: =100*index!Y8/index!X8-100 -> 0.44039725 | H8: =100*index!Z8/index!Y8-100 -> 0.46024111 | I8: =100*index!AA8/index!Z8-100 -> 0.23054414 | J8: =100*index!AB8/index!AA8-100 -> 0.10026245 | K8: =100*index!AC8/index!AB8-100 -> 1.2382776 | L8: =100*index!AD8/index!AC8-100 -> 6.2960736 | M8: =100*index!AE8/index!AD8-100 -> 0.13505252 | ... BG8: =100*index!BY8/index!BX8-100 -> 0.43042589
A9: Galletas de soda | B9: 0.050453635 | C9: B | D9: T | E9: Suby | F9: =100*index!X9/index!W9-100 -> 0.42302405 | G9: =100*index!Y9/index!X9-100 -> 0.48634314 | H9: =100*index!Z9/index!Y9-100 -> 0.14386296 | I9: =100*index!AA9/index!Z9-100 -> 0.52134866 | J9: =100*index!AB9/index!AA9-100 -> 1.1215219 | K9: =100*index!AC9/index!AB9-100 -> 0.4277224 | L9: =100*index!AD9/index!AC9-100 -> 0.24789845 | M9: =100*index!AE9/index!AD9-100 -> 0.12085379 | ... BG9: =100*index!BY9/index!BX9-100 -> 0.17187371
A10: Galletas integrales | B10: 0.019352848 | C10: B | D10: T | E10: Suby | F10: =100*index!X10/index!W10-100 -> 0.014861491 | G10: =100*index!Y10/index!X10-100 -> -0.099061884 | H10: =100*index!Z10/index!Y10-100 -> 0.11205093 | I10: =100*index!AA10/index!Z10-100 -> 0.27634707 | J10: =100*index!AB10/index!AA10-100 -> 0.22027084 | K10: =100*index!AC10/index!AB10-100 -> 1.2408586 | L10: =100*index!AD10/index!AC10-100 -> 1.132193 | M10: =100*index!AE10/index!AD10-100 -> 2.3959416 | ... BG10: =100*index!BY10/index!BX10-100 -> -0.62412539
A11: Corn Flakes | B11: 0.10689881 | C11: B | D11: T | E11: Suby | F11: =100*index!X11/index!W11-100 -> 0.64389778 | G11: =100*index!Y11/index!X11-100 -> 2.117723 | H11: =100*index!Z11/index!Y11-100 -> 1.4928425 | I11: =100*index!AA11/index!Z11-100 -> 0.56325903 | J11: =100*index!AB11/index!AA11-100 -> 0.72768008 | K11: =100*index!AC11/index!AB11-100 -> -0.2034358 | L11: =100*index!AD11/index!AC11-100 -> -0.40317101 | M11: =100*index!AE11/index!AD11-100 -> -0.31656509 | ... BG11: =100*index!BY11/index!BX11-100 -> -0.65026296
A12: Avena | B12: 0.071995783 | C12: B | D12: T | E12: Suby | F12: =100*index!X12/index!W12-100 -> 0.27323976 | G12: =100*index!Y12/index!X12-100 -> 0.13098892 | H12: =100*index!Z12/index!Y12-100 -> -0.063021599 | I12: =100*index!AA12/index!Z12-100 -> -0.063061341 | J12: =100*index!AB12/index!AA12-100 -> 0.28586726 | K12: =100*index!AC12/index!AB12-100 -> 0.040994156 | L12: =100*index!AD12/index!AC12-100 -> 0.52508195 | M12: =100*index!AE12/index!AD12-100 -> 0.71667599 | ... BG12: =100*index!BY12/index!BX12-100 -> -0.19203401
A13: Harina de maíz | B13: 0.043458139 | C13: B | D13: T | E13: Suby | F13: =100*index!X13/index!W13-100 -> 2.2214377 | G13: =100*index!Y13/index!X13-100 -> 2.1468043 | H13: =100*index!Z13/index!Y13-100 -> 1.1068994 | I13: =100*index!AA13/index!Z13-100 -> 1.1458242 | J13: =100*index!AB13/index!AA13-100 -> 3.1348972 | K13: =100*index!AC13/index!AB13-100 -> 6.4132957 | L13: =100*index!AD13/index!AC13-100 -> 2.6827973 | M13: =100*index!AE13/index!AD13-100 -> 1.685441 | ... BG13: =100*index!BY13/index!BX13-100 -> 0.72543918
... A365: Trámite para pasaporte (renovación) | B365: 0.027261408 | C365: S | D365: NT | E365: Suby | F365: =100*index!X365/index!W365-100 -> 0 | G365: =100*index!Y365/index!X365-100 -> 0 | H365: =100*index!Z365/index!Y365-100 -> 0 | I365: =100*index!AA365/index!Z365-100 -> 0 | J365: =100*index!AB365/index!AA365-100 -> 0 | K365: =100*index!AC365/index!AB365-100 -> 0 | L365: =100*index!AD365/index!AC365-100 -> 0 | M365: =100*index!AE365/index!AD365-100 -> 0 | ... BG365: =100*index!BY365/index!BX365-100 -> 0

Sheet index_1999
A1: articulo | B1: pond | C1: b_s | D1: t_nt | E1: suby | F1: grupo | G1: clase | H1: 36192 | I1: 36220 | J1: 36251 | K1: 36281 | L1: 36312 | M1: 36342 | N1: 36373 | O1: 36404 | P1: 36434 | Q1: 36465 | R1: 36495 | S1: 36526 | T1: 36557 | U1: 36586 | V1: 36617 | W1: 36647 | X1: 36678 | Y1: 36708 | Z1: 36739 | AA1: 36770 | AB1: 36800 | AC1: 36831 | AD1: 36861 | AE1: 36892 | AF1: 36923 | AG1: 36951 | AH1: 36982 | AI1: 37012 | AJ1: 37043 | AK1: 37073 | AL1: 37104 | AM1: 37135 | AN1: 37165 | AO1: 37196 | AP1: 37226 | AQ1: 37257 | AR1: 37288 | AS1: 37316 | AT1: 37347 | AU1: 37377 | AV1: 37408 | AW1: 37438 | AX1: 37469 | AY1: 37500 | AZ1: 37530 | BA1: 37561 | BB1: 37591 | BC1: 37622 | BD1: 37653 | BE1: 37681 | BF1: 37712 | BG1: 37742 | BH1: 37773 | BI1: 37803 | BJ1: 37834 | BK1: 37865 | BL1: 37895 | BM1: 37926 | BN1: 37956 | BO1: 37987 | BP1: 38018 | BQ1: 38047 | BR1: 38078 | BS1: 38108 | BT1: 38139 | BU1: 38169 | BV1: 38200 | BW1: 38231 | BX1: 38261 | BY1: 38292 | BZ1: 38322 | CA1: 38353 | CB1: 38384 | CC1: 38412 | CD1: 38443 | CE1: 38473 | CF1: 38504 | CG1: 38534 | CH1: 38565 | CI1: 38596 | CJ1: 38626 | CK1: 38657 | CL1: 38687 | CM1: 38718 | CN1: 38749 | CO1: 38777 | CP1: 38808 | CQ1: 38838 | CR1: 38869 | CS1: 38899 | CT1: 38930 | CU1: 38961 | CV1: 38991 | CW1: 39022 | CX1: 39052 | CY1: 39083 | CZ1: 39114 | DA1: 39142 | DB1: 39173 | DC1: 39203 | DD1: 39234 | DE1: 39264 | DF1: 39295 | DG1: 39326 | DH1: 39356 | DI1: 39387 | DJ1: 39417 | DK1: 39448 | DL1: 39479 | DM1: 39508 | DN1: 39539 | DO1: 39569 | DP1: 39600 | DQ1: 39630 | DR1: 39661 | DS1: 39692 | DT1: 39722 | DU1: 39753 | DV1: 39783 | DW1: 39814 | DX1: 39845 | DY1: 39873 | DZ1: 39904 | EA1: 39934 | EB1: 39965 | EC1: 39995 | ED1: 40026 | EE1: 40057 | EF1: 40087 | EG1: 40118 | EH1: 40148 | EI1: 40179 | EJ1: 40210 | EK1: 40238 | EL1: 40269 | EM1: 40299 | EN1: 40330 | EO1: 40360 | EP1: 40391 | EQ1: 40422 | ER1: 40452 | ES1: 40483 | ET1: 40513
A2: Pan sobado | B2: 1.0181724 | C2: B | D2: N | E2: Suby | F2: ALIMENTOS Y BEBIDAS NO ALCOHOLICAS | G2: Pan y cereales | H2: 100 | I2: 100 | J2: 100 | K2: 100 | L2: 100 | M2: 100 | N2: 100 | O2: 100 | P2: 100 | Q2: 100 | R2: 100 | S2: 100 | T2: 100 | U2: 100 | V2: 100 | W2: 100 | X2: 100 | Y2: 100 | Z2: 100 | AA2: 100 | AB2: 100.7 | AC2: 100.31794 | AD2: 100.20692 | AE2: 100.5 | AF2: 100.5 | AG2: 100.5 | AH2: 100.5 | AI2: 100.5 | AJ2: 100.5 | AK2: 100.5 | AL2: 100.5 | AM2: 100.5 | AN2: 100.5 | AO2: 100.5 | AP2: 100.5 | AQ2: 100.5 | AR2: 100.5 | AS2: 100.5 | AT2: 100.5 | AU2: 100.5 | AV2: 100.5 | AW2: 100.5 | AX2: 100.5 | AY2: 136.5 | AZ2: 150 | BA2: 150 | BB2: 160 | BC2: 200 | BD2: 200 | BE2: 200 | BF2: 200 | BG2: 200 | BH2: 200 | BI2: 200 | BJ2: 201.80846 | BK2: 200.8 | BL2: 200.3 | BM2: 200.3 | BN2: 200.3 | BO2: 207.52451 | BP2: 242.9 | BQ2: 242.9 | BR2: 242.9 | BS2: 242.9 | BT2: 242.9 | BU2: 242.9 | BV2: 242.9 | BW2: 242.9 | BX2: 242.9 | BY2: 242.9 | BZ2: 242.9 | CA2: 242.9 | CB2: 242.9 | CC2: 242.9 | CD2: 242.9 | CE2: 223 | CF2: 217.43905 | CG2: 214.4257 | CH2: 216.69765 | CI2: 219 | CJ2: 219 | CK2: 217.03751 | CL2: 217 | CM2: 217 | CN2: 217.5 | CO2: 217.5 | CP2: 217.5 | CQ2: 217.5 | CR2: 217.5 | CS2: 217.5 | CT2: 217.5 | CU2: 217.5 | CV2: 217.5 | CW2: 220 | CX2: 268 | CY2: 268 | CZ2: 268 | DA2: 268 | DB2: 268 | DC2: 266 | DD2: 259.8 | DE2: 259.8 | DF2: 259.8 | DG2: 259.8 | DH2: 259.8 | DI2: 259.8 | DJ2: 260 | DK2: 306.53578 | DL2: 295.99345 | DM2: 311.7 | DN2: 322.3 | DO2: 312.83712 | DP2: 309.03692 | DQ2: 311.8186 | DR2: 328.10874 | DS2: 328.2 | DT2: 327.08397 | DU2: 319.76233 | DV2: 316.87477 | DW2: 315.03853 | DX2: 310.26686 | DY2: 312.96479 | DZ2: 319.16559 | EA2: 320.34975 | EB2: 314.19997 | EC2: 315.1 | ED2: 315.8 | EE2: 314.11076 | EF2: 321.17121 | EG2: 318.35336 | EH2: 316.1 | EI2: 316.84819 | EJ2: 322.26734 | EK2: 325.11308 | EL2: 325.6 | EM2: 328.6 | EN2: 329.8 | EO2: 328.1 | EP2: 331 | EQ2: 333.8 | ER2: 343.1 | ES2: 342.7 | ET2: 343
A3: Pan de agua | B3: 0.82888618 | C3: B | D3: N | E3: Suby | F3: ALIMENTOS Y BEBIDAS NO ALCOHOLICAS | G3: Pan y cereales | H3: 100 | I3: 100 | J3: 100 | K3: 100 | L3: 100 | M3: 100 | N3: 100 | O3: 100 | P3: 100 | Q3: 100 | R3: 100 | S3: 100 | T3: 100 | U3: 100 | V3: 100 | W3: 100 | X3: 100 | Y3: 99.999712 | Z3: 99.999359 | AA3: 100.12944 | AB3: 101.4 | AC3: 100.16054 | AD3: 101.4 | AE3: 101.8 | AF3: 101.8 | AG3: 101.8 | AH3: 101.8 | AI3: 101.8 | AJ3: 101.8 | AK3: 101.8 | AL3: 101.8 | AM3: 101.8 | AN3: 101.8 | AO3: 101.8 | AP3: 101.8 | AQ3: 101.8 | AR3: 101.8 | AS3: 101.8 | AT3: 101.8 | AU3: 101.8 | AV3: 101.8 | AW3: 101.8 | AX3: 101.8 | AY3: 137.9 | AZ3: 150 | BA3: 150 | BB3: 160 | BC3: 200 | BD3: 200 | BE3: 200 | BF3: 200 | BG3: 200 | BH3: 200 | BI3: 200 | BJ3: 203.5 | BK3: 203.5 | BL3: 201.1 | BM3: 201.1 | BN3: 201.1 | BO3: 211.35069 | BP3: 251.1 | BQ3: 251.1 | BR3: 251.1 | BS3: 251.1 | BT3: 251.1 | BU3: 251.1 | BV3: 251.1 | BW3: 251.1 | BX3: 251.1 | BY3: 251.1 | BZ3: 251.1 | CA3: 251.1 | CB3: 251.1 | CC3: 251.1 | CD3: 251.1 | CE3: 230.5 | CF3: 225 | CG3: 225 | CH3: 227 | CI3: 233 | CJ3: 236.06731 | CK3: 229.27844 | CL3: 227.93324 | CM3: 227.9 | CN3: 228.2 | CO3: 228.2 | CP3: 228.2 | CQ3: 228.24627 | CR3: 228.2 | CS3: 228.2 | CT3: 228.2 | CU3: 228.2 | CV3: 230.9 | CW3: 235.2 | CX3: 270 | CY3: 270 | CZ3: 270 | DA3: 270 | DB3: 270 | DC3: 268 | DD3: 260 | DE3: 260 | DF3: 260 | DG3: 260.2 | DH3: 260.2 | DI3: 260.2 | DJ3: 261 | DK3: 311.94185 | DL3: 299.95776 | DM3: 322.4 | DN3: 325.57075 | DO3: 314.39141 | DP3: 311.46725 | DQ3: 314.97704 | DR3: 330.98291 | DS3: 337.9 | DT3: 342.9 | DU3: 330.16138 | DV3: 327.04678 | DW3: 327.14766 | DX3: 326.05273 | DY3: 323.39708 | DZ3: 326.95522 | EA3: 324.54023 | EB3: 330.6413 | EC3: 333.33599 | ED3: 331.81149 | EE3: 334.66981 | EF3: 336 | EG3: 338.3 | EH3: 329.4 | EI3: 330.15403 | EJ3: 334.3377 | EK3: 330.7 | EL3: 328.6844 | EM3: 331.44723 | EN3: 335.10622 | EO3: 335.1 | EP3: 339.2 | EQ3: 357.3 | ER3: 360.3 | ES3: 352.1 | ET3: 351.3
A4: Bizcochos | B4: 0.12191197 | C4: B | D4: T | E4: Suby | F4: ALIMENTOS Y BEBIDAS NO ALCOHOLICAS | G4: Pan y cereales | H4: 100.28818 | I4: 100.47883 | J4: 101.06589 | K4: 103.14383 | L4: 103.95926 | M4: 104.79434 | N4: 105.84228 | O4: 106.02567 | P4: 106.83783 | Q4: 108.72413 | R4: 109.69348 | S4: 110.03406 | T4: 111.34399 | U4: 113.25648 | V4: 113.28268 | W4: 113.28268 | X4: 113.70186 | Y4: 115.27378 | Z4: 115.27378 | AA4: 115.27378 | AB4: 116.16453 | AC4: 118.67959 | AD4: 119.83233 | AE4: 123.08095 | AF4: 125.75321 | AG4: 127.90149 | AH4: 127.90149 | AI4: 128.66125 | AJ4: 128.66125 | AK4: 128.66125 | AL4: 128.66125 | AM4: 128.89704 | AN4: 130.59995 | AO4: 131.22871 | AP4: 131.22871 | AQ4: 131.22871 | AR4: 131.77888 | AS4: 132.56484 | AT4: 132.56484 | AU4: 135.73487 | AV4: 135.73487 | AW4: 135.73487 | AX4: 135.73487 | AY4: 135.73487 | AZ4: 135.73487 | BA4: 135.73487 | BB4: 136.36364 | BC4: 142.88708 | BD4: 143.35866 | BE4: 143.41106 | BF4: 143.72544 | BG4: 144.11842 | BH4: 144.11842 | BI4: 156.61514 | BJ4: 157.16531 | BK4: 157.16531 | BL4: 157.82028 | BM4: 164.23893 | BN4: 170.00262 | BO4: 184.41184 | BP4: 188.31543 | BQ4: 190.48991 | BR4: 201.40824 | BS4: 210.10482 | BT4: 221.84962 | BU4: 223.31674 | BV4: 224.94105 | BW4: 228.97564 | BX4: 228.97564 | BY4: 229.36861 | BZ4: 227.06314 | CA4: 223.63112 | CB4: 223.63112 | CC4: 220.4087 | CD4: 223.73592 | CE4: 223.73592 | CF4: 223.73592 | CG4: 223.73592 | CH4: 223.73592 | CI4: 223.73592 | CJ4: 222.60938 | CK4: 214.14724 | CL4: 214.14724 | CM4: 215.56196 | CN4: 215.56196 | CO4: 219.57034 | CP4: 218.47 | CQ4: 217.44826 | CR4: 218.5486 | CS4: 218.5486 | CT4: 223.8734 | CU4: 223.86691 | CV4: 226.0152 | CW4: 228.94944 | CX4: 231.22871 | CY4: 232.64344 | CZ4: 232.87922 | DA4: 233.08881 | DB4: 233.97957 | DC4: 235.13633 | DD4: 232.90542 | DE4: 233.95337 | DF4: 234.08436 | DG4: 233.21981 | DH4: 232.87922 | DI4: 231.33351 | DJ4: 235.1585 | DK4: 234.21535 | DL4: 232.25046 | DM4: 230.54755 | DN4: 230.12837 | DO4: 229.23762 | DP4: 227.92769 | DQ4: 226.61776 | DR4: 218.88918 | DS4: 222.94996 | DT4: 224.18129 | DU4: 221.61383 | DV4: 217.44826 | DW4: 217.97223 | DX4: 217.29107 | DY4: 219.17736 | DZ4: 224.8584 | EA4: 229.6044 | EB4: 225.30783 | EC4: 225.30783 | ED4: 224.54807 | EE4: 216.00734 | EF4: 226.04139 | EG4: 230.86193 | EH4: 225.36023 | EI4: 214.98559 | EJ4: 216.37412 | EK4: 232.27666 | EL4: 226.93215 | EM4: 230.04978 | EN4: 222.68797 | EO4: 223.70972 | EP4: 215.37857 | EQ4: 212.49673 | ER4: 209.1957 | ES4: 193.86953 | ET4: 192.5596
A5: Avena | B5: 0.14351735 | C5: B | D5: T | E5: Suby | F5: ALIMENTOS Y BEBIDAS NO ALCOHOLICAS | G5: Pan y cereales | H5: 100.7551 | I5: 102.95428 | J5: 103.18258 | K5: 104.23899 | L5: 105.54663 | M5: 106.28838 | N5: 107.83044 | O5: 107.83712 | P5: 109.62981 | Q5: 114.53939 | R5: 116.08812 | S5: 116.48865 | T5: 117.65123 | U5: 117.66355 | V5: 117.67023 | W5: 117.67023 | X5: 117.67023 | Y5: 117.71028 | Z5: 117.71028 | AA5: 118.53138 | AB5: 119.8466 | AC5: 120 | AD5: 120.37383 | AE5: 120.37383 | AF5: 120.37383 | AG5: 120.37383 | AH5: 120.37383 | AI5: 120.37383 | AJ5: 120.37383 | AK5: 120.37383 | AL5: 120.37383 | AM5: 120.37383 | AN5: 120.37383 | AO5: 118.95194 | AP5: 117.9239 | AQ5: 118.06409 | AR5: 116.68892 | AS5: 116.68892 | AT5: 115.247 | AU5: 114.79306 | AV5: 113.56376 | AW5: 112.91055 | AX5: 113.09079 | AY5: 113.47797 | AZ5: 113.21762 | BA5: 114.1522 | BB5: 119.32577 | BC5: 122.43658 | BD5: 123.63818 | BE5: 128.54473 | BF5: 130.64753 | BG5: 131.34179 | BH5: 144.98985 | BI5: 145.8478 | BJ5: 146.59546 | BK5: 150.32043 | BL5: 161.81575 | BM5: 165.8478 | BN5: 166.45527 | BO5: 181.35514 | BP5: 185.78104 | BQ5: 190.92123 | BR5: 205.06008 | BS5: 206.18158 | BT5: 206.8024 | BU5: 219.01757 | BV5: 237.89052 | BW5: 251.63026 | BX5: 261.45527 | BY5: 250.66966 | BZ5: 245.09015 | CA5: 236.00801 | CB5: 231.1749 | CC5: 234.69292 | CD5: 233.24433 | CE5: 231.1749 | CF5: 222.42991 | CG5: 231.12817 | CH5: 232.08421 | CI5: 233.33778 | CJ5: 233.40454 | CK5: 235.29372 | CL5: 238.43709 | CM5: 233.87183 | CN5: 235.64753 | CO5: 235.95461 | CP5: 234.62617 | CQ5: 236.30174 | CR5: 235.06008 | CS5: 240.22564 | CT5: 240.22697 | CU5: 234.25234 | CV5: 239.13218 | CW5: 240.5741 | CX5: 244.1522 | CY5: 249.07552 | CZ5: 250.86162 | DA5: 250.98798 | DB5: 252.04315 | DC5: 253.19092 | DD5: 252.38362 | DE5: 254.60614 | DF5: 256.502 | DG5: 256.62884 | DH5: 258.51135 | DI5: 262.7592 | DJ5: 266.01719 | DK5: 267.42991 | DL5: 270.13341 | DM5: 272.82377 | DN5: 270.34511 | DO5: 277.18291 | DP5: 285.1774 | DQ5: 286.62466 | DR5: 288.14369 | DS5: 287.25634 | DT5: 286.749 | DU5: 292.42323 | DV5: 284.22563 | DW5: 290.91455 | DX5: 293.63818 | DY5: 288.4186 | DZ5: 291.00801 | EA5: 293.14116 | EB5: 293.55069 | EC5: 289.79973 | ED5: 291.22547 | EE5: 294.29239 | EF5: 289.96662 | EG5: 290.63418 | EH5: 293.88518 | EI5: 289.02537 | EJ5: 291.90657 | EK5: 287.8972 | EL5: 287.4032 | EM5: 291.26836 | EN5: 293.23097 | EO5: 294.60614 | EP5: 292.93725 | EQ5: 287.94393 | ER5: 309.1522 | ES5: 311.82911 | ET5: 312.85047
A6: Arroz | B6: 3.9941727 | C6: B | D6: N | E6: Ex | F6: ALIMENTOS Y BEBIDAS NO ALCOHOLICAS | G6: Pan y cereales | H6: 100.62348 | I6: 100.87763 | J6: 101.77783 | K6: 101.12364 | L6: 100.68122 | M6: 100.34045 | N6: 100.52564 | O6: 100.63911 | P6: 100.83588 | Q6: 103.58167 | R6: 103.86172 | S6: 103.87257 | T6: 104.08618 | U6: 103.24581 | V6: 101.1164 | W6: 101.40454 | X6: 101.41574 | Y6: 101.60566 | Z6: 101.65198 | AA6: 101.95694 | AB6: 102.85555 | AC6: 103.13106 | AD6: 104.84493 | AE6: 107.70013 | AF6: 107.7578 | AG6: 107.7578 | AH6: 107.7578 | AI6: 107.77194 | AJ6: 107.77194 | AK6: 106.45277 | AL6: 104.98612 | AM6: 106.2013 | AN6: 106.74692 | AO6: 106.70162 | AP6: 106.98262 | AQ6: 107.02549 | AR6: 106.75371 | AS6: 107.88372 | AT6: 108.12499 | AU6: 108.36968 | AV6: 107.88436 | AW6: 107.15831 | AX6: 107.13955 | AY6: 107.67183 | AZ6: 108.01802 | BA6: 108.10375 | BB6: 108.42433 | BC6: 109.18947 | BD6: 109.98265 | BE6: 110.76104 | BF6: 111.26302 | BG6: 115.06566 | BH6: 118.00475 | BI6: 122.67336 | BJ6: 126.25017 | BK6: 127.86227 | BL6: 151.07198 | BM6: 158.58889 | BN6: 178.73941 | BO6: 215.93329 | BP6: 309.05409 | BQ6: 333.90402 | BR6: 321.59091 | BS6: 307.04845 | BT6: 300.67565 | BU6: 306.27561 | BV6: 294.0312 | BW6: 262.97539 | BX6: 260.42247 | BY6: 259.11842 | BZ6: 255.39901 | CA6: 255.79916 | CB6: 264.29038 | CC6: 267.886 | CD6: 268.64711 | CE6: 266.32558 | CF6: 262.43432 | CG6: 263.24768 | CH6: 264.81611 | CI6: 267.75549 | CJ6: 268.53229 | CK6: 273.11063 | CL6: 276.45172 | CM6: 277.52267 | CN6: 276.12021 | CO6: 276.50823 | CP6: 275.50235 | CQ6: 275.6699 | CR6: 276.60178 | CS6: 276.86659 | CT6: 276.05043 | CU6: 276.53246 | CV6: 276.20774 | CW6: 276.3169 | CX6: 279.07261 | CY6: 280.61362 | CZ6: 279.31808 | DA6: 279.34518 | DB6: 279.50685 | DC6: 278.0332 | DD6: 276.94001 | DE6: 276.55484 | DF6: 276.59845 | DG6: 275.31484 | DH6: 275.92312 | DI6: 278.86558 | DJ6: 281.27125 | DK6: 280.42316 | DL6: 282.49771 | DM6: 282.41784 | DN6: 295.70056 | DO6: 294.94165 | DP6: 304.99884 | DQ6: 319.73826 | DR6: 330.29645 | DS6: 339.07163 | DT6: 348.83292 | DU6: 349.65208 | DV6: 355.02647 | DW6: 358.12662 | DX6: 359.91221 | DY6: 363.22517 | DZ6: 362.19439 | EA6: 363.15458 | EB6: 358.9728 | EC6: 358.41683 | ED6: 360.91556 | EE6: 358.72541 | EF6: 359.78461 | EG6: 360.60394 | EH6: 362.5884 | EI6: 363.89891 | EJ6: 365.48906 | EK6: 364.18865 | EL6: 364.40586 | EM6: 363.12781 | EN6: 360.21085 | EO6: 357.46472 | EP6: 357.83858 | EQ6: 359.39325 | ER6: 356.88839 | ES6: 354.92265 | ET6: 354.96685
A7: Spaghetti | B7: 0.2336262 | C7: B | D7: T | E7: Suby | F7: ALIMENTOS Y BEBIDAS NO ALCOHOLICAS | G7: Pan y cereales | H7: 100.39894 | I7: 100.50532 | J7: 100.51862 | K7: 100.51862 | L7: 100.53191 | M7: 100.54521 | N7: 100.55851 | O7: 100.57181 | P7: 102.65957 | Q7: 102.67287 | R7: 102.68617 | S7: 102.69947 | T7: 102.71277 | U7: 102.73936 | V7: 102.75266 | W7: 102.75266 | X7: 102.75266 | Y7: 102.75266 | Z7: 102.75266 | AA7: 102.85904 | AB7: 103.41755 | AC7: 103.78989 | AD7: 104.3883 | AE7: 104.4016 | AF7: 104.4016 | AG7: 104.4016 | AH7: 104.4016 | AI7: 104.52128 | AJ7: 104.52128 | AK7: 104.68085 | AL7: 104.9734 | AM7: 104.9734 | AN7: 104.9734 | AO7: 104.9734 | AP7: 105.37234 | AQ7: 105.37234 | AR7: 105.37234 | AS7: 108.44415 | AT7: 109.19009 | AU7: 109.19815 | AV7: 109.49468 | AW7: 109.32181 | AX7: 109.33511 | AY7: 110.25266 | AZ7: 111.2766 | BA7: 111.2766 | BB7: 116.39628 | BC7: 121.59531 | BD7: 123.75759 | BE7: 125.94415 | BF7: 126.11702 | BG7: 129.57447 | BH7: 140.57136 | BI7: 153.16351 | BJ7: 161.22531 | BK7: 161.2234 | BL7: 161.46277 | BM7: 166.2331 | BN7: 263.37766 | BO7: 278.55204 | BP7: 287.69947 | BQ7: 309.43036 | BR7: 317.44003 | BS7: 319.25985 | BT7: 320 | BU7: 320.07979 | BV7: 322.65613 | BW7: 307.79325 | BX7: 291.66767 | BY7: 265.94285 | BZ7: 263.01995 | CA7: 259.10904 | CB7: 260.07979 | CC7: 263.55837 | CD7: 258.76676 | CE7: 255.46796 | CF7: 252.20146 | CG7: 249.81383 | CH7: 248.20363 | CI7: 249.64096 | CJ7: 249.64096 | CK7: 249.95071 | CL7: 250.07102 | CM7: 251.94898 | CN7: 252.65444 | CO7: 252.5266 | CP7: 248.59033 | CQ7: 248.74537 | CR7: 252.08485 | CS7: 254.31387 | CT7: 256.84576 | CU7: 255.79787 | CV7: 253.65897 | CW7: 252.80082 | CX7: 253.41927 | CY7: 253.67021 | CZ7: 253.90422 | DA7: 253.93617 | DB7: 252.39362 | DC7: 252.21618 | DD7: 246.80851 | DE7: 252.38032 | DF7: 252.88564 | DG7: 257.48958 | DH7: 266.40308 | DI7: 268.81925 | DJ7: 276.39288 | DK7: 277.42364 | DL7: 278.35656 | DM7: 280.42504 | DN7: 282.46132 | DO7: 284.2195 | DP7: 302.14577 | DQ7: 310.48964 | DR7: 314.77565 | DS7: 317.5133 | DT7: 319.80891 | DU7: 315.85106 | DV7: 309.21187 | DW7: 307.519 | DX7: 305.16362 | DY7: 298.19779 | DZ7: 294.17998 | EA7: 290.60302 | EB7: 291.54084 | EC7: 291.49078 | ED7: 291.37724 | EE7: 292.75404 | EF7: 287.54947 | EG7: 286.55024 | EH7: 288.97606 | EI7: 289.46359 | EJ7: 289.73709 | EK7: 288.7367 | EL7: 287.94909 | EM7: 288.00532 | EN7: 284.8108 | EO7: 285.19947 | EP7: 284.89362 | EQ7: 285.43883 | ER7: 284.49468 | ES7: 282.85167 | ET7: 287.14643
A8: Fideos | B8: 0.17218626 | C8: B | D8: T | E8: Suby | F8: ALIMENTOS Y BEBIDAS NO ALCOHOLICAS | G8: Pan y cereales | H8: 100.19262 | I8: 100.2168 | J8: 100.2439 | K8: 100.33875 | L8: 100.46854 | M8: 100.55556 | N8: 100.70461 | O8: 100.71816 | P8: 101.07523 | Q8: 101.13979 | R8: 101.50261 | S8: 101.95731 | T8: 102.26287 | U8: 102.35837 | V8: 102.37127 | W8: 102.37127 | X8: 102.37127 | Y8: 102.43902 | Z8: 102.43902 | AA8: 102.57453 | AB8: 104.25474 | AC8: 104.39024 | AD8: 104.39024 | AE8: 104.91208 | AF8: 105.1084 | AG8: 105.1084 | AH8: 105.1084 | AI8: 105.88076 | AJ8: 105.88076 | AK8: 105.97561 | AL8: 106.34146 | AM8: 106.34146 | AN8: 106.34146 | AO8: 106.34146 | AP8: 106.99187 | AQ8: 106.99187 | AR8: 106.99187 | AS8: 110.33875 | AT8: 110.84638 | AU8: 110.8526 | AV8: 111.00271 | AW8: 110.86721 | AX8: 110.90786 | AY8: 111.99187 | AZ8: 112.31707 | BA8: 112.31707 | BB8: 117.89973 | BC8: 123.09216 | BD8: 125.15986 | BE8: 127.04607 | BF8: 127.35356 | BG8: 128.46496 | BH8: 142.42776 | BI8: 156.1273 | BJ8: 164.13371 | BK8: 164.39024 | BL8: 164.39024 | BM8: 169.15063 | BN8: 267.42547 | BO8: 284.10603 | BP8: 293.02168 | BQ8: 314.52349 | BR8: 322.84477 | BS8: 324.96049 | BT8: 325.59621 | BU8: 326.16531 | BV8: 328.95399 | BW8: 313.25778 | BX8: 297.17299 | BY8: 270.52507 | BZ8: 267.21683 | CA8: 263.72629 | CB8: 264.49864 | CC8: 268.76893 | CD8: 263.72799 | CE8: 261.40948 | CF8: 256.852 | CG8: 253.45528 | CH8: 252.26282 | CI8: 253.18428 | CJ8: 253.18428 | CK8: 254.53732 | CL8: 254.74341 | CM8: 256.12466 | CN8: 256.12466 | CO8: 256.88347 | CP8: 253.34186 | CQ8: 253.05192 | CR8: 256.63957 | CS8: 258.80899 | CT8: 261.19612 | CU8: 259.5122 | CV8: 258.59079 | CW8: 258.08223 | CX8: 258.21044 | CY8: 258.27913 | CZ8: 258.93666 | DA8: 259.02439 | DB8: 256.91057 | DC8: 256.61242 | DD8: 255.48398 | DE8: 257.79133 | DF8: 257.87263 | DG8: 261.53733 | DH8: 270.80315 | DI8: 273.45764 | DJ8: 281.2962 | DK8: 282.11583 | DL8: 283.4297 | DM8: 285.26981 | DN8: 288.02158 | DO8: 290.02044 | DP8: 307.65338 | DQ8: 315.89017 | DR8: 320.61999 | DS8: 323.68564 | DT8: 325.60736 | DU8: 321.36856 | DV8: 314.93725 | DW8: 313.95866 | DX8: 310.90673 | DY8: 303.52562 | DZ8: 299.7389 | EA8: 297.17991 | EB8: 297.72651 | EC8: 297.52887 | ED8: 297.69388 | EE8: 298.87953 | EF8: 293.87417 | EG8: 293.34688 | EH8: 294.02439 | EI8: 295.4228 | EJ8: 295.76624 | EK8: 293.87534 | EL8: 293.44105 | EM8: 293.59079 | EN8: 289.87858 | EO8: 292.08672 | EP8: 291.26016 | EQ8: 290.2439 | ER8: 289.5122 | ES8: 288.94858 | ET8: 292.7399
A9: Carne corriente de res | B9: 0.68664786 | C9: B | D9: T | E9: Suby | F9: ALIMENTOS Y BEBIDAS NO ALCOHOLICAS | G9: Carnes | H9: 100.74842 | I9: 102.57119 | J9: 103.07394 | K9: 105.06089 | L9: 105.6323 | M9: 105.89544 | N9: 107.11327 | O9: 107.50609 | P9: 105.43108 | Q9: 105.43595 | R9: 105.44082 | S9: 105.99028 | T9: 106.38091 | U9: 106.54298 | V9: 104.82142 | W9: 104.99269 | X9: 104.99269 | Y9: 104.99269 | Z9: 105.01325 | AA9: 105.14856 | AB9: 106.09788 | AC9: 106.13097 | AD9: 106.48807 | AE9: 107.40867 | AF9: 107.40867 | AG9: 107.64735 | AH9: 108.11495 | AI9: 108.28057 | AJ9: 108.42669 | AK9: 108.97224 | AL9: 108.97224 | AM9: 108.97224 | AN9: 108.97224 | AO9: 108.97224 | AP9: 108.97224 | AQ9: 108.69946 | AR9: 108.69946 | AS9: 108.46389 | AT9: 109.21652 | AU9: 109.64929 | AV9: 109.64929 | AW9: 109.64929 | AX9: 109.93668 | AY9: 109.93668 | AZ9: 109.93668 | BA9: 109.93668 | BB9: 109.93668 | BC9: 110.46761 | BD9: 110.46761 | BE9: 111.05699 | BF9: 111.37847 | BG9: 111.37847 | BH9: 111.48258 | BI9: 113.28614 | BJ9: 114.66147 | BK9: 116.25426 | BL9: 120.87189 | BM9: 132.87871 | BN9: 141.55382 | BO9: 174.71992 | BP9: 199.92207 | BQ9: 220.11411 | BR9: 223.69622 | BS9: 227.31464 | BT9: 233.65541 | BU9: 235.9961 | BV9: 238.50433 | BW9: 240.03958 | BX9: 232.09648 | BY9: 227.73502 | BZ9: 223.38129 | CA9: 222.67901 | CB9: 225.4944 | CC9: 227.71067 | CD9: 226.68777 | CE9: 229.11349 | CF9: 231.78465 | CG9: 234.5056 | CH9: 236.89492 | CI9: 237.21672 | CJ9: 237.23793 | CK9: 234.67121 | CL9: 236.63906 | CM9: 238.28544 | CN9: 238.28544 | CO9: 238.83098 | CP9: 239.7691 | CQ9: 242.39254 | CR9: 243.74087 | CS9: 245.01292 | CT9: 246.74535 | CU9: 247.55967 | CV9: 252.0135 | CW9: 254.59776 | CX9: 256.72586 | CY9: 254.04614 | CZ9: 251.59602 | DA9: 251.41257 | DB9: 249.85874 | DC9: 252.38188 | DD9: 250.52119 | DE9: 255.56746 | DF9: 251.9258 | DG9: 252.11324 | DH9: 252.0248 | DI9: 252.26011 | DJ9: 255.57473 | DK9: 256.20555 | DL9: 257.93204 | DM9: 256.08149 | DN9: 257.80321 | DO9: 259.62494 | DP9: 267.8073 | DQ9: 271.03264 | DR9: 271.31028 | DS9: 273.07842 | DT9: 275.21958 | DU9: 276.84894 | DV9: 271.17876 | DW9: 266.14022 | DX9: 270.39711 | DY9: 273.37837 | DZ9: 275.59327 | EA9: 269.06965 | EB9: 272.22114 | EC9: 269.37893 | ED9: 270.19971 | EE9: 268.27551 | EF9: 271.44158 | EG9: 274.73316 | EH9: 282.28933 | EI9: 281.31239 | EJ9: 273.97459 | EK9: 270.453 | EL9: 275.49455 | EM9: 275.70385 | EN9: 269.59571 | EO9: 268.07599 | EP9: 261.6415 | EQ9: 268.30005 | ER9: 277.07258 | ES9: 275.26536 | ET9: 281.83371
A10: Carne de bola | B10: 0.28513343 | C10: B | D10: T | E10: Suby | F10: ALIMENTOS Y BEBIDAS NO ALCOHOLICAS | G10: Carnes | H10: 100.81541 | I10: 100.98423 | J10: 101.09283 | K10: 102.16336 | L10: 102.83733 | M10: 103.35335 | N10: 105.21699 | O10: 105.64556 | P10: 101.59469 | Q10: 102.40908 | R10: 102.41259 | S10: 102.77766 | T10: 102.79521 | U10: 102.91608 | V10: 102.50824 | W10: 102.53896 | X10: 102.74607 | Y10: 102.74607 | Z10: 103.09587 | AA10: 103.78993 | AB10: 104.52929 | AC10: 104.63109 | AD10: 104.63109 | AE10: 104.63109 | AF10: 106.01063 | AG10: 106.7513 | AH10: 107.50542 | AI10: 107.76577 | AJ10: 108.49501 | AK10: 108.67845 | AL10: 109.16638 | AM10: 109.62272 | AN10: 109.62272 | AO10: 110.24755 | AP10: 110.24755 | AQ10: 110.81972 | AR10: 110.81972 | AS10: 111.10757 | AT10: 111.16022 | AU10: 111.96408 | AV10: 111.96408 | AW10: 111.96408 | AX10: 112.50817 | AY10: 112.50817 | AZ10: 113.45946 | BA10: 114.27384 | BB10: 114.47744 | BC10: 114.47744 | BD10: 114.84602 | BE10: 114.96888 | BF10: 114.97941 | BG10: 114.97941 | BH10: 116.96974 | BI10: 121.12592 | BJ10: 125.69983 | BK10: 129.61028 | BL10: 133.13812 | BM10: 142.38326 | BN10: 154.91242 | BO10: 175.74597 | BP10: 197.62909 | BQ10: 210.33282 | BR10: 214.21503 | BS10: 224.36694 | BT10: 229.1304 | BU10: 235.57879 | BV10: 237.35488 | BW10: 243.17603 | BX10: 237.9557 | BY10: 238.27412 | BZ10: 231.25412 | CA10: 229.7097 | CB10: 234.10963 | CC10: 237.48839 | CD10: 237.1514 | CE10: 238.09216 | CF10: 241.61999 | CG10: 242.9855 | CH10: 248.5844 | CI10: 250.12716 | CJ10: 251.76823 | CK10: 253.04995 | CL10: 255.34463 | CM10: 260.78264 | CN10: 266.53249 | CO10: 266.68344 | CP10: 269.58293 | CQ10: 272.26479 | CR10: 275.49883 | CS10: 279.15197 | CT10: 282.43409 | CU10: 284.26646 | CV10: 284.94394 | CW10: 287.04912 | CX10: 288.00491 | CY10: 287.01705 | CZ10: 285.45293 | DA10: 282.57801 | DB10: 278.33758 | DC10: 279.10052 | DD10: 273.11779 | DE10: 279.10283 | DF10: 275.04845 | DG10: 270.22882 | DH10: 265.25124 | DI10: 259.58213 | DJ10: 255.51912 | DK10: 253.48827 | DL10: 254.69701 | DM10: 255.56987 | DN10: 255.81559 | DO10: 257.03366 | DP10: 258.39214 | DQ10: 260.96869 | DR10: 264.24379 | DS10: 261.75499 | DT10: 262.42804 | DU10: 262.72002 | DV10: 264.02615 | DW10: 268.85249 | DX10: 270.04485 | DY10: 272.60544 | DZ10: 276.27548 | EA10: 275.55235 | EB10: 276.7404 | EC10: 278.7869 | ED10: 285.7363 | EE10: 288.812 | EF10: 293.18258 | EG10: 292.06631 | EH10: 284.71226 | EI10: 288.90003 | EJ10: 289.39849 | EK10: 289.444 | EL10: 288.28924 | EM10: 290.37084 | EN10: 292.47702 | EO10: 292.00664 | EP10: 288.74558 | EQ10: 287.46082 | ER10: 289.13522 | ES10: 288.31511 | ET10: 290.19884
A11: Carne molida de res | B11: 0.10307208 | C11: B | D11: T | E11: Suby | F11: ALIMENTOS Y BEBIDAS NO ALCOHOLICAS | G11: Carnes | H11: 100.18125 | I11: 100.86833 | J11: 101.13628 | K11: 102.32485 | L11: 104.1443 | M11: 104.17916 | N11: 105.71628 | O11: 106.20077 | P11: 103.0286 | Q11: 103.72952 | R11: 104.27531 | S11: 104.56605 | T11: 106.17985 | U11: 106.20425 | V11: 104.32206 | W11: 104.51377 | X11: 104.51377 | Y11: 104.56605 | Z11: 104.56605 | AA11: 104.80307 | AB11: 107.1558 | AC11: 107.24991 | AD11: 107.48693 | AE11: 107.88428 | AF11: 108.42802 | AG11: 108.67898 | AH11: 108.67898 | AI11: 109.27152 | AJ11: 109.4458 | AK11: 109.4458 | AL11: 110.0244 | AM11: 110.31718 | AN11: 110.31718 | AO11: 110.31718 | AP11: 110.74242 | AQ11: 110.73893 | AR11: 110.73893 | AS11: 110.66574 | AT11: 110.70408 | AU11: 111.35502 | AV11: 112.37713 | AW11: 112.37713 | AX11: 112.37713 | AY11: 112.37713 | AZ11: 113.12652 | BA11: 114.39526 | BB11: 114.5068 | BC11: 114.84141 | BD11: 115.15162 | BE11: 115.90101 | BF11: 115.90101 | BG11: 115.93935 | BH11: 118.70059 | BI11: 122.42942 | BJ11: 123.03939 | BK11: 129.15301 | BL11: 129.63402 | BM11: 137.92262 | BN11: 148.21192 | BO11: 166.93621 | BP11: 191.34867 | BQ11: 205.22482 | BR11: 207.65562 | BS11: 208.79749 | BT11: 217.96793 | BU11: 222.16103 | BV11: 226.14151 | BW11: 233.35768 | BX11: 231.08851 | BY11: 232.21331 | BZ11: 228.58708 | CA11: 226.80725 | CB11: 229.81178 | CC11: 232.71095 | CD11: 229.95817 | CE11: 230.86297 | CF11: 231.46044 | CG11: 231.80899 | CH11: 235.60474 | CI11: 236.44899 | CJ11: 236.63297 | CK11: 234.90415 | CL11: 236.23562 | CM11: 234.51471 | CN11: 236.29488 | CO11: 233.32869 | CP11: 230.98989 | CQ11: 233.22761 | CR11: 235.12587 | CS11: 236.6 | CT11: 236.6016 | CU11: 236.9397 | CV11: 239.44277 | CW11: 240.13942 | CX11: 240.63785 | CY11: 242.24468 | CZ11: 238.95434 | DA11: 235.18499 | DB11: 235.40606 | DC11: 234.66531 | DD11: 232.23423 | DE11: 229.22273 | DF11: 227.832 | DG11: 229.43883 | DH11: 231.08052 | DI11: 233.86546 | DJ11: 230.51825 | DK11: 233.23109 | DL11: 235.00523 | DM11: 235.16556 | DN11: 234.79261 | DO11: 234.90066 | DP11: 242.30048 | DQ11: 246.71965 | DR11: 248.96333 | DS11: 248.92297 | DT11: 250.89918 | DU11: 252.49564 | DV11: 255.34857 | DW11: 253.43994 | DX11: 254.07426 | DY11: 252.22896 | DZ11: 261.2362 | EA11: 259.1809 | EB11: 255.95799 | EC11: 255.32604 | ED11: 259.61615 | EE11: 261.75261 | EF11: 261.06657 | EG11: 255.34696 | EH11: 265.73371 | EI11: 263.23458 | EJ11: 262.12966 | EK11: 261.68003 | EL11: 267.59847 | EM11: 268.25222 | EN11: 266.80028 | EO11: 266.94667 | EP11: 264.5312 | EQ11: 265.38515 | ER11: 259.66887 | ES11: 247.32863 | ET11: 244.00837
A12: Pollo fresco | B12: 3.9629572 | C12: B | D12: N | E12: Ex | F12: ALIMENTOS Y BEBIDAS NO ALCOHOLICAS | G12: Carnes | H12: 94.787744 | I12: 104.20266 | J12: 105.2802 | K12: 104.06552 | L12: 97.665462 | M12: 97.061374 | N12: 103.77884 | O12: 105.50261 | P12: 109.50856 | Q12: 108.33954 | R12: 104.6761 | S12: 104.44584 | T12: 103.96128 | U12: 103.04542 | V12: 101.77215 | W12: 101.64557 | X12: 96.944526 | Y12: 100.92015 | Z12: 110.70306 | AA12: 109.01207 | AB12: 104.65793 | AC12: 101.20291 | AD12: 103.26136 | AE12: 106.07031 | AF12: 104.97394 | AG12: 103.36851 | AH12: 100.38255 | AI12: 101.45942 | AJ12: 104.81013 | AK12: 109.4248 | AL12: 113.1493 | AM12: 113.31724 | AN12: 112.76652 | AO12: 107.15204 | AP12: 108.48212 | AQ12: 110.33319 | AR12: 112.85182 | AS12: 115.28667 | AT12: 114.3065 | AU12: 105.58497 | AV12: 107.79374 | AW12: 110.81162 | AX12: 115.99151 | AY12: 116.09084 | AZ12: 115.35369 | BA12: 119.0618 | BB12: 125.91214 | BC12: 131.22507 | BD12: 131.83172 | BE12: 131.07967 | BF12: 130.6478 | BG12: 130.05068 | BH12: 145.33857 | BI12: 134.88293 | BJ12: 146.8131 | BK12: 166.68759 | BL12: 178.1236 | BM12: 205.0484 | BN12: 207.30454 | BO12: 210.23827 | BP12: 250.0968 | BQ12: 252.05996 | BR12: 244.9516 | BS12: 255.86998 | BT12: 270.46165 | BU12: 287.09605 | BV12: 298.21349 | BW12: 282.51552 | BX12: 268.50717 | BY12: 249.97022 | BZ12: 241.56965 | CA12: 249.70715 | CB12: 224.09048 | CC12: 197.14073 | CD12: 207.09769 | CE12: 203.62855 | CF12: 195.80045 | CG12: 197.78109 | CH12: 201.63403 | CI12: 221.07169 | CJ12: 218.11201 | CK12: 213.57791 | CL12: 224.71564 | CM12: 228.65227 | CN12: 223.25391 | CO12: 219.06216 | CP12: 203.35815 | CQ12: 205.35671 | CR12: 219.95532 | CS12: 221.32539 | CT12: 222.18247 | CU12: 223.75279 | CV12: 221.80265 | CW12: 220.30683 | CX12: 223.3605 | CY12: 203.41201 | CZ12: 198.34698 | DA12: 193.37799 | DB12: 200.32835 | DC12: 208.80119 | DD12: 227.44109 | DE12: 228.20551 | DF12: 223.00819 | DG12: 221.66791 | DH12: 222.88332 | DI12: 226.31169 | DJ12: 246.01638 | DK12: 247.07372 | DL12: 213.83405 | DM12: 238.90905 | DN12: 261.60405 | DO12: 255.33854 | DP12: 284.1274 | DQ12: 271.51217 | DR12: 277.69882 | DS12: 290.45421 | DT12: 308.02012 | DU12: 311.86633 | DV12: 321.81887 | DW12: 328.77737 | DX12: 325.51453 | DY12: 316.46903 | DZ12: 280.22416 | EA12: 262.85601 | EB12: 276.46948 | EC12: 302.0905 | ED12: 306.23468 | EE12: 283.97996 | EF12: 281.62786 | EG12: 285.0073 | EH12: 292.82204 | EI12: 297.27039 | EJ12: 296.98497 | EK12: 299.60511 | EL12: 294.28697 | EM12: 295.9838 | EN12: 300.70737 | EO12: 306.85034 | EP12: 317.56515 | EQ12: 320.08935 | ER12: 309.23306 | ES12: 299.51087 | ET12: 301.77058
A13: Carne de gallina | B13: 0.12617543 | C13: B | D13: N | E13: Ex | F13: ALIMENTOS Y BEBIDAS NO ALCOHOLICAS | G13: Carnes | H13: 98.859649 | I13: 107.23589 | J13: 107.71053 | K13: 105.89474 | L13: 102.37719 | M13: 101.40351 | N13: 104.54386 | O13: 105.35088 | P13: 108.15859 | Q13: 107.22644 | R13: 105.191 | S13: 105.23684 | T13: 103.48921 | U13: 102.63158 | V13: 101.31579 | W13: 100.87719 | X13: 98.245614 | Y13: 100 | Z13: 105.41162 | AA13: 105.08772 | AB13: 102.63158 | AC13: 100 | AD13: 101.31579 | AE13: 103.07018 | AF13: 102.19298 | AG13: 101.31579 | AH13: 100 | AI13: 100.87719 | AJ13: 103.50877 | AK13: 105.70175 | AL13: 107.46491 | AM13: 107.89474 | AN13: 108.15789 | AO13: 101.98246 | AP13: 102.89474 | AQ13: 103.94737 | AR13: 105.52632 | AS13: 107.89474 | AT13: 108.20175 | AU13: 106.19298 | AV13: 108.59649 | AW13: 111.25439 | AX13: 118.35088 | AY13: 118.4386 | AZ13: 117.10526 | BA13: 117.68421 | BB13: 131.83394 | BC13: 135.52632 | BD13: 137.84211 | BE13: 136.01754 | BF13: 135.73684 | BG13: 134.76316 | BH13: 150.73684 | BI13: 145.97368 | BJ13: 152.46491 | BK13: 159.42105 | BL13: 176.04386 | BM13: 217.80702 | BN13: 224.68421 | BO13: 242.39474 | BP13: 292.4386 | BQ13: 294.7193 | BR13: 280.32456 | BS13: 288.35965 | BT13: 301.83333 | BU13: 317.11404 | BV13: 329.89474 | BW13: 311.29308 | BX13: 295.59649 | BY13: 289.14035 | BZ13: 279.22807 | CA13: 284.18421 | CB13: 249.35088 | CC13: 220.25439 | CD13: 226.51754 | CE13: 225.31579 | CF13: 224.68421 | CG13: 227.45614 | CH13: 231.72807 | CI13: 250.85965 | CJ13: 246.77193 | CK13: 232.00877 | CL13: 247.96241 | CM13: 247.11404 | CN13: 246.07895 | CO13: 244.70175 | CP13: 227.05263 | CQ13: 225.98246 | CR13: 245.52205 | CS13: 252.01754 | CT13: 253.90529 | CU13: 254.38596 | CV13: 250.96204 | CW13: 247.40351 | CX13: 248.51754 | CY13: 233.74561 | CZ13: 218.65789 | DA13: 214.64035 | DB13: 220.57018 | DC13: 239.5 | DD13: 254.55263 | DE13: 260.03509 | DF13: 258.81579 | DG13: 248.64035 | DH13: 249.03509 | DI13: 253.58772 | DJ13: 257.30702 | DK13: 257.92779 | DL13: 240.54386 | DM13: 256.47368 | DN13: 296.23684 | DO13: 281.18421 | DP13: 324.71053 | DQ13: 301.05263 | DR13: 309.39474 | DS13: 314.61404 | DT13: 337.12281 | DU13: 339.97368 | DV13: 348.20175 | DW13: 371.02632 | DX13: 368.00877 | DY13: 366.89537 | DZ13: 328.07018 | EA13: 304.00877 | EB13: 312.29825 | EC13: 327.83333 | ED13: 333.96491 | EE13: 316.91228 | EF13: 308.81579 | EG13: 323.15789 | EH13: 325.13158 | EI13: 328.97368 | EJ13: 319.66667 | EK13: 323.23684 | EL13: 332.43758 | EM13: 338.87719 | EN13: 340.33333 | EO13: 340.74561 | EP13: 361.87719 | EQ13: 366 | ER13: 362.27193 | ES13: 346.87593 | ET13: 334.96491
... A182: Servicios funerarios | B182: 0.030858248 | C182: S | D182: N | E182: Suby | F182: BIENES Y SERVICIOS DIVERSOS | G182: OTROS SERVICIOS | H182: 100.32792 | I182: 100.36857 | J182: 101.34716 | K182: 101.60255 | L182: 101.64295 | M182: 101.66735 | N182: 101.83821 | O182: 101.88563 | P182: 101.90054 | Q182: 105.48879 | R182: 106.5495 | S182: 106.92244 | T182: 108.94649 | U182: 111.06549 | V182: 111.06846 | W182: 111.49495 | X182: 111.85843 | Y182: 113.45027 | Z182: 113.53104 | AA182: 113.55339 | AB182: 113.55913 | AC182: 113.55921 | AD182: 113.80479 | AE182: 113.856 | AF182: 113.85615 | AG182: 113.88975 | AH182: 113.9809 | AI182: 115.70788 | AJ182: 115.71237 | AK182: 115.83465 | AL182: 115.8347 | AM182: 115.83546 | AN182: 117.39924 | AO182: 118.21509 | AP182: 118.21512 | AQ182: 118.42136 | AR182: 118.42591 | AS182: 118.42626 | AT182: 118.42646 | AU182: 118.42658 | AV182: 118.42664 | AW182: 118.42673 | AX182: 118.42678 | AY182: 119.57097 | AZ182: 121.79775 | BA182: 121.7978 | BB182: 123.80763 | BC182: 130.28227 | BD182: 130.28227 | BE182: 130.28241 | BF182: 131.92096 | BG182: 131.92096 | BH182: 132.08394 | BI182: 132.08396 | BJ182: 132.08398 | BK182: 135.77291 | BL182: 138.22438 | BM182: 138.92803 | BN182: 140.28107 | BO182: 159.70635 | BP182: 163.52251 | BQ182: 165.10689 | BR182: 168.10006 | BS182: 180.48336 | BT182: 182.8735 | BU182: 182.8735 | BV182: 182.8735 | BW182: 182.8735 | BX182: 195.75078 | BY182: 199.02597 | BZ182: 190.98503 | CA182: 189.53835 | CB182: 203.01429 | CC182: 203.0154 | CD182: 204.15789 | CE182: 204.15789 | CF182: 205.60025 | CG182: 197.44975 | CH182: 199.43625 | CI182: 207.87907 | CJ182: 210.98865 | CK182: 210.98865 | CL182: 210.98865 | CM182: 212.91017 | CN182: 215.22494 | CO182: 216.37817 | CP182: 216.70437 | CQ182: 217.64528 | CR182: 218.16983 | CS182: 218.29326 | CT182: 218.43682 | CU182: 218.43682 | CV182: 219.61569 | CW182: 219.9393 | CX182: 219.9393 | CY182: 220.41162 | CZ182: 220.41162 | DA182: 220.63645 | DB182: 220.74675 | DC182: 220.75182 | DD182: 220.98334 | DE182: 221.17116 | DF182: 221.43655 | DG182: 221.48083 | DH182: 221.69347 | DI182: 221.8819 | DJ182: 221.93293 | DK182: 222.41616 | DL182: 222.68304 | DM182: 223.08387 | DN182: 223.88697 | DO182: 224.13323 | DP182: 224.55907 | DQ182: 225.08178 | DR182: 225.75701 | DS182: 226.35233 | DT182: 226.87293 | DU182: 227.49018 | DV182: 227.83139 | DW182: 228.12559 | DX182: 228.38225 | DY182: 230.05881 | DZ182: 230.58793 | EA182: 231.97277 | EB182: 233.7421 | EC182: 235.05105 | ED182: 235.07925 | EE182: 235.66695 | EF182: 237.54971 | EG182: 239.34299 | EH182: 239.38128 | EI182: 240.7619 | EJ182: 241.41113 | EK182: 241.62831 | EL182: 242.17653 | EM182: 243.2367 | EN182: 243.35831 | EO182: 241.8858 | EP182: 242.73239 | EQ182: 243.29067 | ER182: 243.33931 | ES182: 244.80604 | ET182: 244.81215

Sheet index_2010
A1: articulo | B1: pond | C1: b_s | D1: t_nt | E1: suby | F1: grupo | G1: clase | H1: 40513 | I1: 40544 | J1: 40575 | K1: 40603 | L1: 40634 | M1: 40664 | N1: 40695 | O1: 40725 | P1: 40756 | Q1: 40787 | R1: 40817 | S1: 40848 | T1: 40878 | U1: 40909 | V1: 40940 | W1: 40969 | X1: 41000 | Y1: 41030 | Z1: 41061 | AA1: 41091 | AB1: 41122 | AC1: 41153 | AD1: 41183 | AE1: 41214 | AF1: 41244 | AG1: 41275 | AH1: 41306 | AI1: 41334 | AJ1: 41365 | AK1: 41395 | AL1: 41426 | AM1: 41456 | AN1: 41487 | AO1: 41518 | AP1: 41548 | AQ1: 41579 | AR1: 41609 | AS1: 41640 | AT1: 41671 | AU1: 41699 | AV1: 41730 | AW1: 41760 | AX1: 41791 | AY1: 41821 | AZ1: 41852 | BA1: 41883 | BB1: 41913 | BC1: 41944 | BD1: 41974 | BE1: 42005 | BF1: 42036 | BG1: 42064 | BH1: 42095 | BI1: 42125 | BJ1: 42156 | BK1: 42186 | BL1: 42217 | BM1: 42248 | BN1: 42278 | BO1: 42309 | BP1: 42339 | BQ1: 42370 | BR1: 42401 | BS1: 42430 | BT1: 42461 | BU1: 42491 | BV1: 42522 | BW1: 42552 | BX1: 42583 | BY1: 42614 | BZ1: 42644 | CA1: 42675 | CB1: 42705 | CC1: 42736 | CD1: 42767 | CE1: 42795 | CF1: 42826 | CG1: 42856 | CH1: 42887 | CI1: 42917 | CJ1: 42948 | CK1: 42979 | CL1: 43009 | CM1: 43040 | CN1: 43070 | CO1: 43101 | CP1: 43132 | CQ1: 43160 | CR1: 43191 | CS1: 43221 | CT1: 43252 | CU1: 43282 | CV1: 43313 | CW1: 43344 | CX1: 43374 | CY1: 43405 | CZ1: 43435 | DA1: 43466 | DB1: 43497 | DC1: 43525 | DD1: 43556 | DE1: 43586 | DF1: 43617 | DG1: 43647 | DH1: 43678 | DI1: 43709 | DJ1: 43739 | DK1: 43770 | DL1: 43800 | DM1: 43831 | DN1: 43862 | DO1: 43891 | DP1: 43922 | DQ1: 43952 | DR1: 43983 | DS1: 44013 | DT1: 44044 | DU1: 44075
A2: Pan sobado | B2: 0.55702 | C2: B | D2: N | E2: Suby | F2: ALIMENTOS Y BEBIDAS NO ALCOHOLICAS | G2: Pan y cereales | H2: 100 | I2: 107.66 | J2: 114.73 | K2: 116.89 | L2: 117.3 | M2: 117.86 | N2: 117.93 | O2: 117.99 | P2: 117.99 | Q2: 118 | R2: 118 | S2: 118 | T2: 118.01 | U2: 118.01 | V2: 117.97 | W2: 117.97 | X2: 117.97 | Y2: 117.97 | Z2: 117.97 | AA2: 117.97 | AB2: 117.97 | AC2: 117.98 | AD2: 117.74 | AE2: 118.01 | AF2: 117.61 | AG2: 117.79 | AH2: 117.8 | AI2: 117.8 | AJ2: 117.8 | AK2: 117.82 | AL2: 117.82 | AM2: 117.817 | AN2: 117.817 | AO2: 117.849 | AP2: 117.814 | AQ2: 117.799 | AR2: 117.84 | AS2: 117.84 | AT2: 117.84 | AU2: 117.84 | AV2: 117.855 | AW2: 117.855 | AX2: 117.884 | AY2: 117.884 | AZ2: 117.983 | BA2: 117.983 | BB2: 117.983 | BC2: 117.983 | BD2: 117.983 | BE2: 117.983 | BF2: 117.983 | BG2: 118.083 | BH2: 118.209 | BI2: 118.495 | BJ2: 118.495 | BK2: 118.495 | BL2: 118.515 | BM2: 118.547 | BN2: 118.547 | BO2: 118.547 | BP2: 118.547 | BQ2: 118.564 | BR2: 118.564 | BS2: 118.564 | BT2: 118.598 | BU2: 118.677 | BV2: 118.688 | BW2: 118.688 | BX2: 118.688 | BY2: 118.711 | BZ2: 118.717 | CA2: 118.717 | CB2: 118.753 | CC2: 118.862 | CD2: 118.885 | CE2: 118.885 | CF2: 118.83 | CG2: 118.883 | CH2: 118.885 | CI2: 118.887 | CJ2: 118.838 | CK2: 118.888 | CL2: 118.888 | CM2: 118.933 | CN2: 118.882 | CO2: 119.108 | CP2: 119.134 | CQ2: 119.119 | CR2: 119.162 | CS2: 119.119 | CT2: 119.165 | CU2: 119.203 | CV2: 119.212 | CW2: 119.199 | CX2: 119.127 | CY2: 119.187 | CZ2: 119.198 | DA2: 119.21 | DB2: 119.224 | DC2: 119.229 | DD2: 119.314 | DE2: 119.385 | DF2: 119.419 | DG2: 119.359 | DH2: 119.36 | DI2: 119.258 | DJ2: 119.224 | DK2: 119.263 | DL2: 119.278 | DM2: 119.411 | DN2: 119.382 | DO2: 119.44 | DP2: 119.394 | DQ2: 119.38 | DR2: 119.435 | DS2: 119.277 | DT2: 119.378 | DU2: 119.359
A3: Pan de agua | B3: 0.52219 | C3: B | D3: N | E3: Suby | F3: ALIMENTOS Y BEBIDAS NO ALCOHOLICAS | G3: Pan y cereales | H3: 100 | I3: 106.58 | J3: 113.65 | K3: 115.11 | L3: 115.19 | M3: 115.51 | N3: 115.66 | O3: 115.73 | P3: 115.49 | Q3: 115.5 | R3: 115.5 | S3: 115.5 | T3: 115.5 | U3: 115.5 | V3: 115.52 | W3: 115.52 | X3: 115.52 | Y3: 115.52 | Z3: 115.51 | AA3: 115.53 | AB3: 115.53 | AC3: 115.49 | AD3: 115.6 | AE3: 115.75 | AF3: 115.81 | AG3: 115.91 | AH3: 115.91 | AI3: 115.95 | AJ3: 115.95 | AK3: 116.01 | AL3: 116.01 | AM3: 116.01 | AN3: 116.01 | AO3: 116.01 | AP3: 116.019 | AQ3: 115.97 | AR3: 116.019 | AS3: 116.019 | AT3: 116.019 | AU3: 116.019 | AV3: 116.05 | AW3: 116.068 | AX3: 116.068 | AY3: 116.068 | AZ3: 116.08 | BA3: 116.127 | BB3: 116.126 | BC3: 116.126 | BD3: 116.126 | BE3: 116.126 | BF3: 116.127 | BG3: 116.141 | BH3: 116.411 | BI3: 116.449 | BJ3: 116.449 | BK3: 116.449 | BL3: 116.458 | BM3: 116.458 | BN3: 116.458 | BO3: 116.711 | BP3: 116.711 | BQ3: 116.711 | BR3: 116.817 | BS3: 116.817 | BT3: 116.825 | BU3: 116.826 | BV3: 116.826 | BW3: 116.826 | BX3: 116.835 | BY3: 116.835 | BZ3: 116.835 | CA3: 116.835 | CB3: 116.835 | CC3: 116.856 | CD3: 116.901 | CE3: 116.901 | CF3: 116.903 | CG3: 116.903 | CH3: 116.931 | CI3: 116.934 | CJ3: 116.934 | CK3: 116.938 | CL3: 116.986 | CM3: 117.247 | CN3: 117.15 | CO3: 117.196 | CP3: 117.234 | CQ3: 117.26 | CR3: 117.366 | CS3: 117.401 | CT3: 117.47 | CU3: 117.314 | CV3: 116.511 | CW3: 116.427 | CX3: 116.53 | CY3: 116.585 | CZ3: 116.592 | DA3: 116.592 | DB3: 116.669 | DC3: 117.103 | DD3: 117.312 | DE3: 117.406 | DF3: 117.441 | DG3: 117.52 | DH3: 117.65 | DI3: 117.612 | DJ3: 117.631 | DK3: 117.701 | DL3: 117.639 | DM3: 117.745 | DN3: 117.695 | DO3: 117.723 | DP3: 117.662 | DQ3: 117.684 | DR3: 117.712 | DS3: 117.6 | DT3: 117.654 | DU3: 117.582
A4: Pan rebanado | B4: 0.05519 | C4: B | D4: N | E4: Suby | F4: ALIMENTOS Y BEBIDAS NO ALCOHOLICAS | G4: Pan y cereales | H4: 100 | I4: 101.13 | J4: 101.78 | K4: 101.85 | L4: 101.79 | M4: 102.53 | N4: 106.19 | O4: 107.2 | P4: 108.43 | Q4: 108.78 | R4: 109.43 | S4: 109.76 | T4: 109.84 | U4: 113.32 | V4: 114.88 | W4: 115.28 | X4: 116.26 | Y4: 116.11 | Z4: 116.31 | AA4: 116.19 | AB4: 115.67 | AC4: 115.66 | AD4: 115.18 | AE4: 115.21 | AF4: 114.78 | AG4: 122.27 | AH4: 129.36 | AI4: 131.62 | AJ4: 133.79 | AK4: 132.51 | AL4: 128.24 | AM4: 126.671 | AN4: 126.937 | AO4: 126.812 | AP4: 126.873 | AQ4: 126.021 | AR4: 125.805 | AS4: 126.02 | AT4: 126.733 | AU4: 126.673 | AV4: 127.153 | AW4: 127.104 | AX4: 126.537 | AY4: 127.29 | AZ4: 126.953 | BA4: 127.177 | BB4: 127.084 | BC4: 126.868 | BD4: 127.2 | BE4: 127.27 | BF4: 127.277 | BG4: 127.233 | BH4: 127.53 | BI4: 127.991 | BJ4: 127.932 | BK4: 127.658 | BL4: 127.078 | BM4: 127.582 | BN4: 127.086 | BO4: 127.255 | BP4: 127.276 | BQ4: 127.093 | BR4: 127.401 | BS4: 127.959 | BT4: 128.018 | BU4: 128.183 | BV4: 127.935 | BW4: 127.861 | BX4: 127.538 | BY4: 127.893 | BZ4: 128.005 | CA4: 128.19 | CB4: 127.709 | CC4: 128.519 | CD4: 128.437 | CE4: 128.845 | CF4: 128.56 | CG4: 128.494 | CH4: 129.004 | CI4: 129.507 | CJ4: 129.298 | CK4: 129.343 | CL4: 129.571 | CM4: 129.359 | CN4: 128.852 | CO4: 129.656 | CP4: 129.735 | CQ4: 130.195 | CR4: 130.085 | CS4: 130.343 | CT4: 130.171 | CU4: 130.201 | CV4: 129.354 | CW4: 129.286 | CX4: 129.342 | CY4: 129.541 | CZ4: 129.698 | DA4: 129.677 | DB4: 129.299 | DC4: 129.452 | DD4: 129.447 | DE4: 129.358 | DF4: 129.647 | DG4: 129.682 | DH4: 129.705 | DI4: 129.521 | DJ4: 129.699 | DK4: 129.748 | DL4: 129.252 | DM4: 129.988 | DN4: 129.898 | DO4: 130.091 | DP4: 130.235 | DQ4: 131.378 | DR4: 131.77 | DS4: 131.496 | DT4: 130.959 | DU4: 131.581
A5: Galletas saladas | B5: 0.17055 | C5: B | D5: T | E5: Suby | F5: ALIMENTOS Y BEBIDAS NO ALCOHOLICAS | G5: Pan y cereales | H5: 100 | I5: 101.1 | J5: 101.86 | K5: 104.07 | L5: 106.81 | M5: 108.28 | N5: 109.14 | O5: 109.53 | P5: 111.5 | Q5: 113.56 | R5: 114.76 | S5: 115.18 | T5: 115.75 | U5: 116.23 | V5: 116.52 | W5: 116.89 | X5: 117.18 | Y5: 117.18 | Z5: 117.97 | AA5: 117.82 | AB5: 117.84 | AC5: 118.36 | AD5: 118.53 | AE5: 118.93 | AF5: 119.26 | AG5: 120.99 | AH5: 121.43 | AI5: 121.83 | AJ5: 121.29 | AK5: 121 | AL5: 121.26 | AM5: 120.922 | AN5: 120.914 | AO5: 122.2 | AP5: 121.994 | AQ5: 121.864 | AR5: 122.364 | AS5: 122.948 | AT5: 122.875 | AU5: 122.864 | AV5: 123.212 | AW5: 123.64 | AX5: 124.153 | AY5: 123.925 | AZ5: 123.576 | BA5: 124.048 | BB5: 124.098 | BC5: 123.819 | BD5: 124.423 | BE5: 124.327 | BF5: 124.805 | BG5: 124.705 | BH5: 124.02 | BI5: 124.295 | BJ5: 124.062 | BK5: 124.102 | BL5: 124.314 | BM5: 124.087 | BN5: 124.885 | BO5: 124.9 | BP5: 124.716 | BQ5: 125.096 | BR5: 124.681 | BS5: 124.551 | BT5: 124.733 | BU5: 124.73 | BV5: 124.71 | BW5: 123.608 | BX5: 122.85 | BY5: 122.986 | BZ5: 122.545 | CA5: 123.317 | CB5: 123.773 | CC5: 124.429 | CD5: 124.354 | CE5: 124.179 | CF5: 124.243 | CG5: 124.308 | CH5: 124.364 | CI5: 124.308 | CJ5: 124.442 | CK5: 125.387 | CL5: 126.079 | CM5: 126.787 | CN5: 127.165 | CO5: 127.409 | CP5: 128.187 | CQ5: 128.006 | CR5: 128.341 | CS5: 128.346 | CT5: 128.726 | CU5: 128.919 | CV5: 129.11 | CW5: 129.401 | CX5: 129.233 | CY5: 129.59 | CZ5: 129.842 | DA5: 130.182 | DB5: 130.496 | DC5: 130.488 | DD5: 130.918 | DE5: 130.769 | DF5: 130.242 | DG5: 129.668 | DH5: 129.501 | DI5: 129.11 | DJ5: 129.08 | DK5: 129.522 | DL5: 129.714 | DM5: 129.666 | DN5: 129.71 | DO5: 129.822 | DP5: 130.179 | DQ5: 130.482 | DR5: 131.104 | DS5: 130.951 | DT5: 131.29 | DU5: 131.322
A6: Bizcochos | B6: 0.12415 | C6: B | D6: T | E6: Suby | F6: ALIMENTOS Y BEBIDAS NO ALCOHOLICAS | G6: Pan y cereales | H6: 100 | I6: 100.88 | J6: 101.07 | K6: 101.39 | L6: 101.83 | M6: 101.85 | N6: 102.12 | O6: 102.14 | P6: 102.45 | Q6: 102.3 | R6: 102.36 | S6: 102.67 | T6: 102.94 | U6: 103.16 | V6: 103.38 | W6: 103.55 | X6: 103.55 | Y6: 103.64 | Z6: 103.74 | AA6: 103.73 | AB6: 103.88 | AC6: 103.81 | AD6: 104.22 | AE6: 104.26 | AF6: 104.49 | AG6: 104.82 | AH6: 105.34 | AI6: 105.36 | AJ6: 105.73 | AK6: 105.73 | AL6: 106.44 | AM6: 106.304 | AN6: 106.85 | AO6: 107.343 | AP6: 107.478 | AQ6: 107.678 | AR6: 107.665 | AS6: 107.988 | AT6: 107.992 | AU6: 108.306 | AV6: 108.401 | AW6: 107.994 | AX6: 108.114 | AY6: 108.472 | AZ6: 108.581 | BA6: 108.908 | BB6: 109.106 | BC6: 109.08 | BD6: 109.176 | BE6: 109.879 | BF6: 110.333 | BG6: 110.326 | BH6: 110.411 | BI6: 110.776 | BJ6: 110.972 | BK6: 111.068 | BL6: 111.164 | BM6: 111.357 | BN6: 111.243 | BO6: 111.438 | BP6: 111.54 | BQ6: 111.59 | BR6: 111.722 | BS6: 111.955 | BT6: 112.005 | BU6: 111.956 | BV6: 112.058 | BW6: 112.074 | BX6: 112.153 | BY6: 112.403 | BZ6: 112.531 | CA6: 112.686 | CB6: 112.888 | CC6: 114.114 | CD6: 114.475 | CE6: 114.956 | CF6: 115.187 | CG6: 115.284 | CH6: 115.16 | CI6: 115.25 | CJ6: 115.329 | CK6: 115.553 | CL6: 115.602 | CM6: 115.637 | CN6: 115.673 | CO6: 115.757 | CP6: 116 | CQ6: 116.315 | CR6: 116.842 | CS6: 116.92 | CT6: 120.263 | CU6: 120.695 | CV6: 127.01 | CW6: 127.614 | CX6: 127.68 | CY6: 127.55 | CZ6: 127.554 | DA6: 127.882 | DB6: 128.441 | DC6: 128.602 | DD6: 128.835 | DE6: 128.549 | DF6: 128.958 | DG6: 128.811 | DH6: 129.015 | DI6: 129.02 | DJ6: 129.105 | DK6: 129.192 | DL6: 129.169 | DM6: 129.183 | DN6: 129.583 | DO6: 129.941 | DP6: 129.863 | DQ6: 130.254 | DR6: 130.931 | DS6: 132.206 | DT6: 132.498 | DU6: 132.741
